<?xml version="1.0" ?>
<mujoco model="lite3">
  <compiler angle="radian" meshdir="../resources/robots/lite3/meshes"/>

  <default>
    <joint limited="true" damping="0.1" frictionloss="0.01"/>
    <geom margin="0.001" condim="3" friction="0.5 0.005 0.0001" contype="1" conaffinity="1"/>
  </default>

  <worldbody>
    <body name="TORSO" pos="0 0 0" euler="0 0 0">
      <inertial mass="5.6056" pos="0 0 0" diaginertia="0.02456 0.05518 0.07016"/>
      <geom type="mesh" mesh="torso.STL" pos="0 0 0" euler="0 0 0" contype="1" conaffinity="1"/>
      <geom type="mesh" mesh="torso.STL" pos="0 0 0" euler="-1.57 0 0" contype="0" conaffinity="0"/>
      <body name="FL_HIP" pos="0.1745 0.062 0" euler="0 0 0">
        <inertial mass="0.550" pos="-0.00601 -0.0066532 0.00034295" diaginertia="0.0003949 0.0004028 0.0004472"/>
        <geom type="mesh" mesh="fl_hip.STL" pos="0 0 0" euler="-1.57 0 0" contype="0" conaffinity="0"/>
        <joint name="FL_HipX_joint" type="hinge" axis="-1 0 0" range="-0.523 0.523"/>
        <body name="FL_THIGH" pos="0 0.09735 0" euler="0 0 0">
          <inertial mass="0.86" pos="-0.0052817 -0.014632 -0.042672" diaginertia="0.005736 0.004960 0.001436"/>
          <geom type="box" pos="0 0 -0.08" euler="0 0 0" contype="1" conaffinity="1" size="0.02 0.02 0.16"/>
          <geom type="mesh" mesh="fl_thigh.STL" pos="0 0 0" euler="-1.57 0 0" contype="0" conaffinity="0"/>
          <joint name="FL_HipY_joint" type="hinge" axis="0 -1 0" range="-2.67 0.314"/>
          <body name="FL_SHANK" pos="0 0 -0.20" euler="0 0 0">
            <inertial mass="0.153" pos="0.0064794 -1.4535E-06 -0.12157" diaginertia="0.00089039 0.00090672 3.1266E-05"/>
            <geom type="box" pos="0 0 -0.09" euler="0 0 0" contype="1" conaffinity="1" size="0.02 0.02 0.18"/>
            <geom type="mesh" mesh="fl_shank_collision.STL" pos="0 0 0" euler="-1.57 0 0" contype="0" conaffinity="0"/>
            <joint name="FL_Knee_joint" type="hinge" axis="0 -1 0" range="0.524 2.792"/>
            <body name="FL_FOOT" pos="0 0 -0.21012" euler="0 0 0">
              <inertial mass="0.02" pos="0 0 0" diaginertia="0 0 0"/>
              <geom type="sphere" pos="0 0 0" euler="1.57079632679 0 0" contype="1" conaffinity="1" size="0.022"/>
              <geom type="sphere" pos="0 0 0" euler="-1.57 0 0" contype="0" conaffinity="0" size="0.022"/>
            </body>
          </body>
        </body>
      </body>
      <body name="FR_HIP" pos="0.1745 -0.062 0" euler="0 0 0">
        <inertial mass="0.550" pos="-0.010579 0.011358 0.00048546" diaginertia="0.0004472 0.0004028 0.0003949"/>
        <geom type="mesh" mesh="fr_hip.STL" pos="0 0 0" euler="-1.57 0 0" contype="0" conaffinity="0"/>
        <joint name="FR_HipX_joint" type="hinge" axis="-1 0 0" range="-0.523 0.523"/>
        <body name="FR_THIGH" pos="0 -0.09735 0" euler="0 0 0">
          <inertial mass="0.86" pos="-0.0039245 0.025256 -0.025146" diaginertia="0.005736 0.004960 0.001436"/>
          <geom type="box" pos="0 0 -0.08" euler="0 0 0" contype="1" conaffinity="1" size="0.02 0.02 0.16"/>
          <geom type="mesh" mesh="fr_thigh.STL" pos="0 0 0" euler="-1.57 0 0" contype="0" conaffinity="0"/>
          <joint name="FR_HipY_joint" type="hinge" axis="0 -1 0" range="-2.67 0.314"/>
          <body name="FR_SHANK" pos="0 0 -0.20" euler="0 0 0">
            <inertial mass="0.153" pos="0.0064794 -1.4552E-06 -0.12157" diaginertia="0.00089039 0.00090672 3.1266E-05"/>
            <geom type="box" pos="0 0 -0.09" euler="0 0 0" contype="1" conaffinity="1" size="0.02 0.02 0.18"/>
            <geom type="mesh" mesh="fr_shank_collision.STL" pos="0 0 0" euler="-1.57 0 0" contype="0" conaffinity="0"/>
            <joint name="FR_Knee_joint" type="hinge" axis="0 -1 0" range="0.524 2.792"/>
            <body name="FR_FOOT" pos="0 0 -0.21012" euler="0 0 0">
              <inertial mass="0.02" pos="0 0 0" diaginertia="0 0 0"/>
              <geom type="sphere" pos="0 0 0" euler="1.57079632679 0 0" contype="1" conaffinity="1" size="0.022"/>
              <geom type="sphere" pos="0 0 0" euler="-1.57 0 0" contype="0" conaffinity="0" size="0.022"/>
            </body>
          </body>
        </body>
      </body>
      <body name="HL_HIP" pos="-0.1745 0.062 0" euler="0 0 0">
        <inertial mass="0.550" pos="0.010905 -0.012636 0.001051" diaginertia="0.0003949 0.0004028 0.0004472"/>
        <geom type="mesh" mesh="hl_hip.STL" pos="0 0 0" euler="-1.57 0 0" contype="0" conaffinity="0"/>
        <joint name="HL_HipX_joint" type="hinge" axis="-1 0 0" range="-0.523 0.523"/>
        <body name="HL_THIGH" pos="0 0.09735 0" euler="0 0 0">
          <inertial mass="0.86" pos="-0.0057137 -0.014631 -0.042453" diaginertia="0.005736 0.004960 0.001436"/>
          <geom type="box" pos="0 0 -0.08" euler="0 0 0" contype="1" conaffinity="1" size="0.02 0.02 0.16"/>
          <geom type="mesh" mesh="hl_thigh.STL" pos="0 0 0" euler="-1.57 0 0" contype="0" conaffinity="0"/>
          <joint name="HL_HipY_joint" type="hinge" axis="0 -1 0" range="-2.67 0.314"/>
          <body name="HL_SHANK" pos="0 0 -0.20" euler="0 0 0">
            <inertial mass="0.153" pos="0.0064794 -1.4558E-06 -0.12157" diaginertia="0.00089039 0.00090672 3.1266E-05"/>
            <geom type="box" pos="0 0 -0.09" euler="0 0 0" contype="1" conaffinity="1" size="0.02 0.02 0.18"/>
            <geom type="mesh" mesh="hl_shank_collision.STL" pos="0 0 0" euler="-1.57 0 0" contype="0" conaffinity="0"/>
            <joint name="HL_Knee_joint" type="hinge" axis="0 -1 0" range="0.524 2.792"/>
            <body name="HL_FOOT" pos="0 0 -0.21012" euler="0 0 0">
              <inertial mass="0.02" pos="0 0 0" diaginertia="0 0 0"/>
              <geom type="sphere" pos="0 0 0" euler="1.57079632679 0 0" contype="1" conaffinity="1" size="0.022"/>
              <geom type="sphere" pos="0 0 0" euler="-1.57 0 0" contype="0" conaffinity="0" size="0.022"/>
            </body>
          </body>
        </body>
      </body>
      <body name="HR_HIP" pos="-0.1745 -0.062 0" euler="0 0 0">
        <inertial mass="0.550" pos="0.010354 0.011423 0.00049498" diaginertia="0.0003949 0.0004028 0.0004472"/>
        <geom type="mesh" mesh="hr_hip.STL" pos="0 0 0" euler="-1.57 0 0" contype="0" conaffinity="0"/>
        <joint name="HR_HipX_joint" type="hinge" axis="-1 0 0" range="-0.523 0.523"/>
        <body name="HR_THIGH" pos="0 -0.09735 0" euler="0 0 0">
          <inertial mass="0.86" pos="-0.0031903 0.02526 -0.025617" diaginertia="0.005736 0.004960 0.001436"/>
          <geom type="box" pos="0 0 -0.08" euler="0 0 0" contype="1" conaffinity="1" size="0.02 0.02 0.16"/>
          <geom type="mesh" mesh="hr_thigh.STL" pos="0 0 0" euler="-1.57 0 0" contype="0" conaffinity="0"/>
          <joint name="HR_HipY_joint" type="hinge" axis="0 -1 0" range="-2.67 0.314"/>
          <body name="HR_SHANK" pos="0 0 -0.20" euler="0 0 0">
            <inertial mass="0.153" pos="0.0064794 -1.4529E-06 -0.12157" diaginertia="0.00089039 0.00090672 3.1266E-05"/>
            <geom type="box" pos="0 0 -0.09" euler="0 0 0" contype="1" conaffinity="1" size="0.02 0.02 0.18"/>
            <geom type="mesh" mesh="hr_shank_collision.STL" pos="0 0 0" euler="-1.57 0 0" contype="0" conaffinity="0"/>
            <joint name="HR_Knee_joint" type="hinge" axis="0 -1 0" range="0.524 2.792"/>
            <body name="HR_FOOT" pos="0 0 -0.21012" euler="0 0 0">
              <inertial mass="0.02" pos="0 0 0" diaginertia="0 0 0"/>
              <geom type="sphere" pos="0 0 0" euler="1.57079632679 0 0" contype="1" conaffinity="1" size="0.022"/>
              <geom type="sphere" pos="0 0 0" euler="-1.57 0 0" contype="0" conaffinity="0" size="0.022"/>
            </body>
          </body>
        </body>
      </body>
      <body name="imu_link" pos="0 0 0.0" euler="0 0 0">
        <inertial mass="0.01" pos="0 0 0" diaginertia="1e-6 1e-6 1e-6"/>
        <geom type="box" pos="0 0 0" euler="0 0 0" contype="1" conaffinity="1" size="0.02 0.02 0.01"/>
        <geom type="box" pos="0 0 0" euler="0 0 0" contype="0" conaffinity="0" size="0.02 0.02 0.01"/>
      </body>
      <body name="depth_camera_link" pos="0.25228 -0.0005 0.07410" euler="0 0 0">
        <inertial mass="0.1" pos="0 0 0" diaginertia="1e-5 1e-5 1e-5"/>
        <geom type="box" pos="0 0 0" euler="0 0 0" contype="1" conaffinity="1" size="0.02 0.05 0.02"/>
        <geom type="box" pos="0 0 0" euler="0 0 0" contype="0" conaffinity="0" size="0.02 0.04 0.02"/>
        <body name="depth_camera_optical_frame" pos="0 0 0" euler="-1.57079632679 0 -1.57079632679">
          <inertial mass="0.001" pos="0 0 0" diaginertia="1e-6 1e-6 1e-6"/>
        </body>
      </body>
    </body>
  </worldbody>

  <actuator>
    <motor name="FL_HipX_joint_motor" joint="FL_HipX_joint" gear="1.0" forcerange="-30 30"/>
    <motor name="FL_HipY_joint_motor" joint="FL_HipY_joint" gear="1.0" forcerange="-30 30"/>
    <motor name="FL_Knee_joint_motor" joint="FL_Knee_joint" gear="1.0" forcerange="-30 30"/>
    <motor name="FR_HipX_joint_motor" joint="FR_HipX_joint" gear="1.0" forcerange="-30 30"/>
    <motor name="FR_HipY_joint_motor" joint="FR_HipY_joint" gear="1.0" forcerange="-30 30"/>
    <motor name="FR_Knee_joint_motor" joint="FR_Knee_joint" gear="1.0" forcerange="-30 30"/>
    <motor name="HL_HipX_joint_motor" joint="HL_HipX_joint" gear="1.0" forcerange="-30 30"/>
    <motor name="HL_HipY_joint_motor" joint="HL_HipY_joint" gear="1.0" forcerange="-30 30"/>
    <motor name="HL_Knee_joint_motor" joint="HL_Knee_joint" gear="1.0" forcerange="-30 30"/>
    <motor name="HR_HipX_joint_motor" joint="HR_HipX_joint" gear="1.0" forcerange="-30 30"/>
    <motor name="HR_HipY_joint_motor" joint="HR_HipY_joint" gear="1.0" forcerange="-30 30"/>
    <motor name="HR_Knee_joint_motor" joint="HR_Knee_joint" gear="1.0" forcerange="-30 30"/>
  </actuator>
</mujoco>
